<?xml version="1.0" ?>
<!-- =================================================================================== -->
<!-- |    This document was autogenerated by xacro from invite_csda10f.xacro           | -->
<!-- |    EDITING THIS FILE BY HAND IS NOT RECOMMENDED                                 | -->
<!-- =================================================================================== -->
<!--Develped by Daniel Ordonez 11.01.2018 - dfordoneza@unal.edu.co
	INFORMATION:
		This xacro file creates the urdf description of Invite's CSDA10F dual-arm robot with 
		both 2-Finger Adaptative Robotiq Grippers (140mm one for the right arm and 80mm one for the left one)
-->
<robot name="motoman_csda10f" xmlns:xacro="http://ros.org/wiki/xacro">
  <!-- link list -->
  <link name="base_link">
    <visual>
      <geometry>
        <mesh filename="package://motoman_csda10f_support/meshes/csda10f/visual/csda_base.STL" scale="0.001 0.001 0.001"/>
      </geometry>
      <material name="blue">
        <color rgba="0.8 0.8 0.8 1"/>
      </material>
    </visual>
    <collision>
      <geometry>
        <mesh filename="package://motoman_csda10f_support/meshes/csda10f/collision/csda_base.stl" scale="0.001 0.001 0.001"/>
      </geometry>
      <material name="yellow">
        <color rgba="0 1 1 1"/>
      </material>
    </collision>
  </link>
  <link name="torso_link_b1">
    <visual>
      <origin rpy="0 0 0" xyz="0 0 0"/>
      <geometry>
        <mesh filename="package://motoman_csda10f_support/meshes/csda10f/visual/csda_axis_b1.STL" scale="0.001 0.001 0.001"/>
      </geometry>
      <material name="silver">
        <color rgba="0.8 0.8 0.8 1"/>
      </material>
    </visual>
    <collision>
      <origin rpy="0 0 0" xyz="0 0 0"/>
      <geometry>
        <mesh filename="package://motoman_csda10f_support/meshes/csda10f/collision/csda_axis_b1.stl" scale="0.001 0.001 0.001"/>
      </geometry>
      <material name="yellow"/>
    </collision>
  </link>
  <link name="torso_link_b2">
    <visual>
      <origin rpy="0 0 0" xyz="0 0 0"/>
      <geometry>
        <mesh filename="package://motoman_csda10f_support/meshes/csda10f/visual/csda_axis_b1.STL" scale="0.001 0.001 0.001"/>
      </geometry>
      <material name="silver">
        <color rgba="0.8 0.8 0.8 1"/>
      </material>
    </visual>
    <collision>
      <origin rpy="0 0 0" xyz="0 0 0"/>
      <geometry>
        <mesh filename="package://motoman_csda10f_support/meshes/csda10f/collision/csda_axis_b1.stl" scale="0.001 0.001 0.001"/>
      </geometry>
      <material name="yellow"/>
    </collision>
  </link>
  <!-- joint list -->
  <joint name="torso_joint_b1" type="revolute">
    <parent link="base_link"/>
    <child link="torso_link_b1"/>
    <origin rpy="0 0 0" xyz="0.0925 0 0.8619"/>
    <axis xyz="0 0 1"/>
    <limit effort="100" lower="-2.9570" upper="2.9570" velocity="2.26"/>
  </joint>
  <joint name="torso_joint_b2" type="revolute">
    <parent link="base_link"/>
    <child link="torso_link_b2"/>
    <origin rpy="0 0 0" xyz="0.0925 0 0.8619"/>
    <axis xyz="0 0 1"/>
    <limit effort="100" lower="-2.9570" upper="2.9570" velocity="2.26"/>
    <mimic joint="torso_joint_b1" multiplier="1" offset="0"/>
  </joint>
  <!-- end of joint list -->
  <link name="arm_left_link_1_s">
    <visual>
      <origin rpy="0 0 0" xyz="0 0 0"/>
      <geometry>
        <mesh filename="package://motoman_csda10f_support/meshes/csda10f/visual/csda_axis_s.STL" scale="0.001 0.001 0.001"/>
      </geometry>
      <material name="silver">
        <color rgba="0.8 0.8 0.8 1"/>
      </material>
    </visual>
    <collision>
      <origin rpy="0 0 0" xyz="0 0 0"/>
      <geometry>
        <mesh filename="package://motoman_csda10f_support/meshes/csda10f/collision/csda_axis_s.stl" scale="0.001 0.001 0.001"/>
      </geometry>
      <material name="yellow"/>
    </collision>
  </link>
  <link name="arm_left_link_2_l">
    <visual>
      <origin rpy="0 0 0" xyz="0 0 0"/>
      <geometry>
        <mesh filename="package://motoman_csda10f_support/meshes/csda10f/visual/csda_axis_l.STL" scale="0.001 0.001 0.001"/>
      </geometry>
      <material name="silver"/>
    </visual>
    <collision>
      <origin rpy="0 0 0" xyz="0 0 0"/>
      <geometry>
        <mesh filename="package://motoman_csda10f_support/meshes/csda10f/collision/csda_axis_l.stl" scale="0.001 0.001 0.001"/>
      </geometry>
      <material name="yellow"/>
    </collision>
  </link>
  <link name="arm_left_link_3_e">
    <visual>
      <origin rpy="0 0 0" xyz="0 0 0"/>
      <geometry>
        <mesh filename="package://motoman_csda10f_support/meshes/csda10f/visual/csda_axis_e.STL" scale="0.001 0.001 0.001"/>
      </geometry>
      <material name="silver"/>
    </visual>
    <collision>
      <origin rpy="0 0 0" xyz="0 0 0"/>
      <geometry>
        <mesh filename="package://motoman_csda10f_support/meshes/csda10f/collision/csda_axis_e.stl" scale="0.001 0.001 0.001"/>
      </geometry>
      <material name="yellow"/>
    </collision>
  </link>
  <link name="arm_left_link_4_u">
    <visual>
      <origin rpy="0 0 0" xyz="0 0 0"/>
      <geometry>
        <mesh filename="package://motoman_csda10f_support/meshes/csda10f/visual/csda_axis_u.STL" scale="0.001 0.001 0.001"/>
      </geometry>
      <material name="silver"/>
    </visual>
    <collision>
      <origin rpy="0 0 0" xyz="0 0 0"/>
      <geometry>
        <mesh filename="package://motoman_csda10f_support/meshes/csda10f/collision/csda_axis_u.stl" scale="0.001 0.001 0.001"/>
      </geometry>
      <material name="yellow"/>
    </collision>
  </link>
  <link name="arm_left_link_5_r">
    <visual>
      <origin rpy="0 0 0" xyz="0 0 0"/>
      <geometry>
        <mesh filename="package://motoman_csda10f_support/meshes/csda10f/visual/csda_axis_r.STL" scale="0.001 0.001 0.001"/>
      </geometry>
      <material name="silver"/>
    </visual>
    <collision>
      <origin rpy="0 0 0" xyz="0 0 0"/>
      <geometry>
        <mesh filename="package://motoman_csda10f_support/meshes/csda10f/collision/csda_axis_r.stl" scale="0.001 0.001 0.001"/>
      </geometry>
      <material name="yellow"/>
    </collision>
  </link>
  <link name="arm_left_link_6_b">
    <visual>
      <origin rpy="0 0 0" xyz="0 0 0"/>
      <geometry>
        <mesh filename="package://motoman_csda10f_support/meshes/csda10f/visual/csda_axis_b.STL" scale="0.001 0.001 0.001"/>
      </geometry>
      <material name="silver"/>
    </visual>
    <collision>
      <origin rpy="0 0 0" xyz="0 0 0"/>
      <geometry>
        <mesh filename="package://motoman_csda10f_support/meshes/csda10f/collision/csda_axis_b.stl" scale="0.001 0.001 0.001"/>
      </geometry>
      <material name="yellow"/>
    </collision>
  </link>
  <link name="arm_left_link_7_t">
    <visual>
      <geometry>
        <mesh filename="package://motoman_csda10f_support/meshes/csda10f/visual/csda_axis_t.STL" scale="0.001 0.001 0.001"/>
      </geometry>
      <material name="silver"/>
    </visual>
    <collision>
      <origin rpy="0 0 0" xyz="0 0 0"/>
      <geometry>
        <mesh filename="package://motoman_csda10f_support/meshes/csda10f/collision/csda_axis_t.stl" scale="0.001 0.001 0.001"/>
      </geometry>
      <material name="yellow"/>
    </collision>
  </link>
  <link name="arm_left_link_tool0"/>
  <joint name="arm_left_joint_1_s" type="revolute">
    <parent link="torso_link_b1"/>
    <child link="arm_left_link_1_s"/>
    <origin rpy="1.57 0 0.0" xyz="0.1 0.023 0.3381"/>
    <axis xyz="0 0 -1"/>
    <limit effort="0" lower="-3.13" upper="3.13" velocity="2.95"/>
  </joint>
  <joint name="arm_left_joint_2_l" type="revolute">
    <parent link="arm_left_link_1_s"/>
    <child link="arm_left_link_2_l"/>
    <origin rpy="-1.57 0 0" xyz="0 0.0454 -0.242"/>
    <axis xyz="0 0 -1"/>
    <limit effort="0" lower="-1.90" upper="1.90" velocity="2.95"/>
  </joint>
  <joint name="arm_left_joint_3_e" type="revolute">
    <parent link="arm_left_link_2_l"/>
    <child link="arm_left_link_3_e"/>
    <origin rpy="1.57 0 0" xyz="0 0.175 -0.04540"/>
    <axis xyz="0 0 -1"/>
    <limit effort="0" lower="-2.95" upper="2.95" velocity="2.95"/>
  </joint>
  <joint name="arm_left_joint_4_u" type="revolute">
    <parent link="arm_left_link_3_e"/>
    <child link="arm_left_link_4_u"/>
    <origin rpy="-1.57 0 0" xyz="0.00001 -0.0155 -0.185"/>
    <axis xyz="0 0 1"/>
    <limit effort="0" lower="-2.36" upper="2.36" velocity="2.95"/>
  </joint>
  <joint name="arm_left_joint_5_r" type="revolute">
    <parent link="arm_left_link_4_u"/>
    <child link="arm_left_link_5_r"/>
    <origin rpy="1.57 0 0" xyz="0.00002 0.1487 0.0155"/>
    <axis xyz="0 0 1"/>
    <limit effort="0" lower="-3.13" upper="3.13" velocity="3.48"/>
  </joint>
  <joint name="arm_left_joint_6_b" type="revolute">
    <parent link="arm_left_link_5_r"/>
    <child link="arm_left_link_6_b"/>
    <origin rpy="-1.57 0 0" xyz="0.00001 0.015 -0.2113"/>
    <axis xyz="0 0 1"/>
    <limit effort="0" lower="-1.90" upper="1.90" velocity="3.48"/>
  </joint>
  <joint name="arm_left_joint_7_t" type="revolute">
    <parent link="arm_left_link_6_b"/>
    <child link="arm_left_link_7_t"/>
    <origin rpy="1.57 0 0" xyz="0 0.118 -0.015"/>
    <axis xyz="0 0 -1"/>
    <limit effort="0" lower="-3.13" upper="3.13" velocity="6.97"/>
  </joint>
  <joint name="arm_left_joint_tool0" type="fixed">
    <origin rpy="3.13 0 0" xyz="0 0 -0.0569999"/>
    <parent link="arm_left_link_7_t"/>
    <child link="arm_left_link_tool0"/>
  </joint>
  <!-- end of joint list -->
  <link name="arm_right_link_1_s">
    <visual>
      <origin rpy="0 0 0" xyz="0 0 0"/>
      <geometry>
        <mesh filename="package://motoman_csda10f_support/meshes/csda10f/visual/csda_axis_s.STL" scale="0.001 0.001 0.001"/>
      </geometry>
      <material name="silver">
        <color rgba="0.8 0.8 0.8 1"/>
      </material>
    </visual>
    <collision>
      <origin rpy="0 0 0" xyz="0 0 0"/>
      <geometry>
        <mesh filename="package://motoman_csda10f_support/meshes/csda10f/collision/csda_axis_s.stl" scale="0.001 0.001 0.001"/>
      </geometry>
      <material name="yellow"/>
    </collision>
  </link>
  <link name="arm_right_link_2_l">
    <visual>
      <origin rpy="0 0 0" xyz="0 0 0"/>
      <geometry>
        <mesh filename="package://motoman_csda10f_support/meshes/csda10f/visual/csda_axis_l.STL" scale="0.001 0.001 0.001"/>
      </geometry>
      <material name="silver"/>
    </visual>
    <collision>
      <origin rpy="0 0 0" xyz="0 0 0"/>
      <geometry>
        <mesh filename="package://motoman_csda10f_support/meshes/csda10f/collision/csda_axis_l.stl" scale="0.001 0.001 0.001"/>
      </geometry>
      <material name="yellow"/>
    </collision>
  </link>
  <link name="arm_right_link_3_e">
    <visual>
      <origin rpy="0 0 0" xyz="0 0 0"/>
      <geometry>
        <mesh filename="package://motoman_csda10f_support/meshes/csda10f/visual/csda_axis_e.STL" scale="0.001 0.001 0.001"/>
      </geometry>
      <material name="silver"/>
    </visual>
    <collision>
      <origin rpy="0 0 0" xyz="0 0 0"/>
      <geometry>
        <mesh filename="package://motoman_csda10f_support/meshes/csda10f/collision/csda_axis_e.stl" scale="0.001 0.001 0.001"/>
      </geometry>
      <material name="yellow"/>
    </collision>
  </link>
  <link name="arm_right_link_4_u">
    <visual>
      <origin rpy="0 0 0" xyz="0 0 0"/>
      <geometry>
        <mesh filename="package://motoman_csda10f_support/meshes/csda10f/visual/csda_axis_u.STL" scale="0.001 0.001 0.001"/>
      </geometry>
      <material name="silver"/>
    </visual>
    <collision>
      <origin rpy="0 0 0" xyz="0 0 0"/>
      <geometry>
        <mesh filename="package://motoman_csda10f_support/meshes/csda10f/collision/csda_axis_u.stl" scale="0.001 0.001 0.001"/>
      </geometry>
      <material name="yellow"/>
    </collision>
  </link>
  <link name="arm_right_link_5_r">
    <visual>
      <origin rpy="0 0 0" xyz="0 0 0"/>
      <geometry>
        <mesh filename="package://motoman_csda10f_support/meshes/csda10f/visual/csda_axis_r.STL" scale="0.001 0.001 0.001"/>
      </geometry>
      <material name="silver"/>
    </visual>
    <collision>
      <origin rpy="0 0 0" xyz="0 0 0"/>
      <geometry>
        <mesh filename="package://motoman_csda10f_support/meshes/csda10f/collision/csda_axis_r.stl" scale="0.001 0.001 0.001"/>
      </geometry>
      <material name="yellow"/>
    </collision>
  </link>
  <link name="arm_right_link_6_b">
    <visual>
      <origin rpy="0 0 0" xyz="0 0 0"/>
      <geometry>
        <mesh filename="package://motoman_csda10f_support/meshes/csda10f/visual/csda_axis_b.STL" scale="0.001 0.001 0.001"/>
      </geometry>
      <material name="silver"/>
    </visual>
    <collision>
      <origin rpy="0 0 0" xyz="0 0 0"/>
      <geometry>
        <mesh filename="package://motoman_csda10f_support/meshes/csda10f/collision/csda_axis_b.stl" scale="0.001 0.001 0.001"/>
      </geometry>
      <material name="yellow"/>
    </collision>
  </link>
  <link name="arm_right_link_7_t">
    <visual>
      <geometry>
        <mesh filename="package://motoman_csda10f_support/meshes/csda10f/visual/csda_axis_t.STL" scale="0.001 0.001 0.001"/>
      </geometry>
      <material name="silver"/>
    </visual>
    <collision>
      <origin rpy="0 0 0" xyz="0 0 0"/>
      <geometry>
        <mesh filename="package://motoman_csda10f_support/meshes/csda10f/collision/csda_axis_t.stl" scale="0.001 0.001 0.001"/>
      </geometry>
      <material name="yellow"/>
    </collision>
  </link>
  <link name="arm_right_link_tool0"/>
  <joint name="arm_right_joint_1_s" type="revolute">
    <parent link="torso_link_b1"/>
    <child link="arm_right_link_1_s"/>
    <origin rpy="1.57 0 -3.14" xyz="0.1 -0.023 0.3381"/>
    <axis xyz="0 0 1"/>
    <limit effort="0" lower="-3.13" upper="3.13" velocity="2.95"/>
  </joint>
  <joint name="arm_right_joint_2_l" type="revolute">
    <parent link="arm_right_link_1_s"/>
    <child link="arm_right_link_2_l"/>
    <origin rpy="-1.57 0 0" xyz="0 0.0454 -0.242"/>
    <axis xyz="0 0 1"/>
    <limit effort="0" lower="-1.90" upper="1.90" velocity="2.95"/>
  </joint>
  <joint name="arm_right_joint_3_e" type="revolute">
    <parent link="arm_right_link_2_l"/>
    <child link="arm_right_link_3_e"/>
    <origin rpy="1.57 0 0" xyz="0 0.175 -0.04540"/>
    <axis xyz="0 0 1"/>
    <limit effort="0" lower="-2.95" upper="2.95" velocity="2.95"/>
  </joint>
  <joint name="arm_right_joint_4_u" type="revolute">
    <parent link="arm_right_link_3_e"/>
    <child link="arm_right_link_4_u"/>
    <origin rpy="-1.57 0 0" xyz="0.00001 -0.0155 -0.185"/>
    <axis xyz="0 0 -1"/>
    <limit effort="0" lower="-2.36" upper="2.36" velocity="2.95"/>
  </joint>
  <joint name="arm_right_joint_5_r" type="revolute">
    <parent link="arm_right_link_4_u"/>
    <child link="arm_right_link_5_r"/>
    <origin rpy="1.57 0 0" xyz="0.00002 0.1487 0.0155"/>
    <axis xyz="0 0 -1"/>
    <limit effort="0" lower="-3.13" upper="3.13" velocity="3.48"/>
  </joint>
  <joint name="arm_right_joint_6_b" type="revolute">
    <parent link="arm_right_link_5_r"/>
    <child link="arm_right_link_6_b"/>
    <origin rpy="-1.57 0 0" xyz="0.00001 0.015 -0.2113"/>
    <axis xyz="0 0 -1"/>
    <limit effort="0" lower="-1.90" upper="1.90" velocity="3.48"/>
  </joint>
  <joint name="arm_right_joint_7_t" type="revolute">
    <parent link="arm_right_link_6_b"/>
    <child link="arm_right_link_7_t"/>
    <origin rpy="1.57 0 0" xyz="0 0.118 -0.015"/>
    <axis xyz="0 0 1"/>
    <limit effort="0" lower="-3.13" upper="3.13" velocity="6.97"/>
  </joint>
  <joint name="arm_right_joint_tool0" type="fixed">
    <origin rpy="3.13 0 0" xyz="0 0 -0.0569999"/>
    <parent link="arm_right_link_7_t"/>
    <child link="arm_right_link_tool0"/>
  </joint>
  <!-- end of joint list -->
  <!--Aluminium Adapter plate for Robotiq coupling and CSDA10F arm flange-->
  <link name="arm_right_link_gripper_adapter_plate">
    <visual>
      <origin rpy="0 0 0" xyz="0 0 0"/>
      <geometry>
        <mesh filename="package://invite_motoman_support/meshes/robotiq-yaskawa_adapter_plate.stl" scale="0.001 0.001 0.001"/>
      </geometry>
      <material name="Aluminium">
        <color rgba="0.816 0.816 0.816 1.0"/>
      </material>
    </visual>
    <collision>
      <origin rpy="1.57079632679 0 0" xyz="0 0.0045 0"/>
      <geometry>
        <cylinder length="0.009" radius="0.038"/>
      </geometry>
      <material name="yellow"/>
    </collision>
  </link>
  <!--Robotiq coupling, that connects the gripper with the Adapter plate; this part host the cable connections of the gripper-->
  <link name="arm_right_link_robotiq_coupling">
    <visual>
      <origin rpy="0 0 0" xyz="0 0 0"/>
      <geometry>
        <mesh filename="package://invite_motoman_support/meshes/robotiq_gripper_coupling.stl" scale="0.001 0.001 0.001"/>
      </geometry>
      <material name="light_balck">
        <color rgba="0.17 0.17 0.17 1.0"/>
      </material>
    </visual>
    <collision>
      <origin rpy="0 0 0" xyz="0 0 0"/>
      <geometry>
        <cylinder length="0.0135" radius="0.038"/>
      </geometry>
      <material name="yellow"/>
    </collision>
  </link>
  --&gt;

		
  <link name="right_gripper_robotiq_arg2f_base_link">
    <inertial>
      <origin rpy="0 0 0" xyz="8.625E-08 -4.6583E-06 0.03145"/>
      <mass value="0.22652"/>
      <inertia ixx="0.00020005" ixy="-4.2442E-10" ixz="-2.9069E-10" iyy="0.00017832" iyz="-3.4402E-08" izz="0.00013478"/>
    </inertial>
    <visual>
      <origin rpy="0 0 0" xyz="0 0 0"/>
      <geometry>
        <mesh filename="package://robotiq_arg2f_model_visualization/meshes/robotiq_arg2f_base_link_fine.stl"/>
      </geometry>
      <material name="">
        <color rgba="0.1 0.1 0.1 1"/>
      </material>
    </visual>
    <collision>
      <origin rpy="0 0 1.57079632679" xyz="0 0 0"/>
      <geometry>
        <mesh filename="package://robotiq_arg2f_model_visualization/meshes/robotiq_arg2f_base_link_coarse.stl"/>
      </geometry>
    </collision>
  </link>
  <link name="right_gripper_left_outer_knuckle">
    <inertial>
      <origin rpy="0 0 0" xyz="-0.000200000000003065 0.0199435877845359 0.0292245259211331"/>
      <mass value="0.00853198276973456"/>
      <inertia ixx="2.89328108496468E-06" ixy="-1.57935047237397E-19" ixz="-1.93980378593255E-19" iyy="1.86719750325683E-06" iyz="-1.21858577871576E-06" izz="1.21905238907251E-06"/>
    </inertial>
    <visual>
      <origin rpy="0 0 0" xyz="0 0 0"/>
      <geometry>
        <mesh filename="package://robotiq_arg2f_model_visualization/meshes/robotiq_arg2f_140_outer_knuckle.stl"/>
      </geometry>
      <material name="">
        <color rgba="0.792156862745098 0.819607843137255 0.933333333333333 1"/>
      </material>
    </visual>
    <collision>
      <origin rpy="0 0 0" xyz="0 0 0"/>
      <geometry>
        <mesh filename="package://robotiq_arg2f_model_visualization/meshes/robotiq_arg2f_140_outer_knuckle.stl"/>
      </geometry>
    </collision>
  </link>
  <link name="right_gripper_left_outer_finger">
    <inertial>
      <origin rpy="0 0 0" xyz="0.00030115855001899 0.0373907951953854 -0.0208027427000385"/>
      <mass value="0.022614240507152"/>
      <inertia ixx="1.52518312458174E-05" ixy="9.76583423954399E-10" ixz="-5.43838577022588E-10" iyy="6.17694243867776E-06" iyz="6.78636130740228E-06" izz="1.16494917907219E-05"/>
    </inertial>
    <visual>
      <origin rpy="0 0 0" xyz="0 0 0"/>
      <geometry>
        <mesh filename="package://robotiq_arg2f_model_visualization/meshes/robotiq_arg2f_140_outer_finger.stl"/>
      </geometry>
      <material name="">
        <color rgba="0.1 0.1 0.1 1"/>
      </material>
    </visual>
    <collision>
      <origin rpy="0 0 0" xyz="0 0 0"/>
      <geometry>
        <mesh filename="package://robotiq_arg2f_model_visualization/meshes/robotiq_arg2f_140_outer_finger.stl"/>
      </geometry>
    </collision>
  </link>
  <link name="right_gripper_left_inner_finger">
    <inertial>
      <origin rpy="0 0 0" xyz="0.000299999999999317 0.0160078233491243 -0.0136945669206257"/>
      <mass value="0.0104003125914103"/>
      <inertia ixx="2.71909453810972E-06" ixy="1.35402465472579E-21" ixz="-7.1817349065269E-22" iyy="7.69100314106116E-07" iyz="6.74715432769696E-07" izz="2.30315190420171E-06"/>
    </inertial>
    <visual>
      <origin rpy="0 0 0" xyz="0 0 0"/>
      <geometry>
        <mesh filename="package://robotiq_arg2f_model_visualization/meshes/robotiq_arg2f_140_inner_finger.stl"/>
      </geometry>
      <material name="">
        <color rgba="0.1 0.1 0.1 1"/>
      </material>
    </visual>
    <collision>
      <origin rpy="0 0 0" xyz="0 0 0"/>
      <geometry>
        <mesh filename="package://robotiq_arg2f_model_visualization/meshes/robotiq_arg2f_140_inner_finger.stl"/>
      </geometry>
    </collision>
  </link>
  <link name="right_gripper_left_inner_knuckle">
    <inertial>
      <origin rpy="0 0 0" xyz="0.000123011831763771 0.0507850843201817 0.00103968640075166"/>
      <mass value="0.0271177346495152"/>
      <inertia ixx="2.61910379223783E-05" ixy="-2.43616858946494E-07" ixz="-6.37789906117123E-09" iyy="2.8270243746167E-06" iyz="-5.37200748039765E-07" izz="2.83695868220296E-05"/>
    </inertial>
    <visual>
      <origin rpy="0 0 0" xyz="0 0 0"/>
      <geometry>
        <mesh filename="package://robotiq_arg2f_model_visualization/meshes/robotiq_arg2f_140_inner_knuckle.stl"/>
      </geometry>
      <material name="">
        <color rgba="0.1 0.1 0.1 1"/>
      </material>
    </visual>
    <collision>
      <origin rpy="0 0 0" xyz="0 0 0"/>
      <geometry>
        <mesh filename="package://robotiq_arg2f_model_visualization/meshes/robotiq_arg2f_140_inner_knuckle.stl"/>
      </geometry>
    </collision>
  </link>
  <link name="right_gripper_right_outer_knuckle">
    <inertial>
      <origin rpy="0 0 0" xyz="-0.000200000000003065 0.0199435877845359 0.0292245259211331"/>
      <mass value="0.00853198276973456"/>
      <inertia ixx="2.89328108496468E-06" ixy="-1.57935047237397E-19" ixz="-1.93980378593255E-19" iyy="1.86719750325683E-06" iyz="-1.21858577871576E-06" izz="1.21905238907251E-06"/>
    </inertial>
    <visual>
      <origin rpy="0 0 0" xyz="0 0 0"/>
      <geometry>
        <mesh filename="package://robotiq_arg2f_model_visualization/meshes/robotiq_arg2f_140_outer_knuckle.stl"/>
      </geometry>
      <material name="">
        <color rgba="0.792156862745098 0.819607843137255 0.933333333333333 1"/>
      </material>
    </visual>
    <collision>
      <origin rpy="0 0 0" xyz="0 0 0"/>
      <geometry>
        <mesh filename="package://robotiq_arg2f_model_visualization/meshes/robotiq_arg2f_140_outer_knuckle.stl"/>
      </geometry>
    </collision>
  </link>
  <link name="right_gripper_right_outer_finger">
    <inertial>
      <origin rpy="0 0 0" xyz="0.00030115855001899 0.0373907951953854 -0.0208027427000385"/>
      <mass value="0.022614240507152"/>
      <inertia ixx="1.52518312458174E-05" ixy="9.76583423954399E-10" ixz="-5.43838577022588E-10" iyy="6.17694243867776E-06" iyz="6.78636130740228E-06" izz="1.16494917907219E-05"/>
    </inertial>
    <visual>
      <origin rpy="0 0 0" xyz="0 0 0"/>
      <geometry>
        <mesh filename="package://robotiq_arg2f_model_visualization/meshes/robotiq_arg2f_140_outer_finger.stl"/>
      </geometry>
      <material name="">
        <color rgba="0.1 0.1 0.1 1"/>
      </material>
    </visual>
    <collision>
      <origin rpy="0 0 0" xyz="0 0 0"/>
      <geometry>
        <mesh filename="package://robotiq_arg2f_model_visualization/meshes/robotiq_arg2f_140_outer_finger.stl"/>
      </geometry>
    </collision>
  </link>
  <link name="right_gripper_right_inner_finger">
    <inertial>
      <origin rpy="0 0 0" xyz="0.000299999999999317 0.0160078233491243 -0.0136945669206257"/>
      <mass value="0.0104003125914103"/>
      <inertia ixx="2.71909453810972E-06" ixy="1.35402465472579E-21" ixz="-7.1817349065269E-22" iyy="7.69100314106116E-07" iyz="6.74715432769696E-07" izz="2.30315190420171E-06"/>
    </inertial>
    <visual>
      <origin rpy="0 0 0" xyz="0 0 0"/>
      <geometry>
        <mesh filename="package://robotiq_arg2f_model_visualization/meshes/robotiq_arg2f_140_inner_finger.stl"/>
      </geometry>
      <material name="">
        <color rgba="0.1 0.1 0.1 1"/>
      </material>
    </visual>
    <collision>
      <origin rpy="0 0 0" xyz="0 0 0"/>
      <geometry>
        <mesh filename="package://robotiq_arg2f_model_visualization/meshes/robotiq_arg2f_140_inner_finger.stl"/>
      </geometry>
    </collision>
  </link>
  <link name="right_gripper_right_inner_knuckle">
    <inertial>
      <origin rpy="0 0 0" xyz="0.000123011831763771 0.0507850843201817 0.00103968640075166"/>
      <mass value="0.0271177346495152"/>
      <inertia ixx="2.61910379223783E-05" ixy="-2.43616858946494E-07" ixz="-6.37789906117123E-09" iyy="2.8270243746167E-06" iyz="-5.37200748039765E-07" izz="2.83695868220296E-05"/>
    </inertial>
    <visual>
      <origin rpy="0 0 0" xyz="0 0 0"/>
      <geometry>
        <mesh filename="package://robotiq_arg2f_model_visualization/meshes/robotiq_arg2f_140_inner_knuckle.stl"/>
      </geometry>
      <material name="">
        <color rgba="0.1 0.1 0.1 1"/>
      </material>
    </visual>
    <collision>
      <origin rpy="0 0 0" xyz="0 0 0"/>
      <geometry>
        <mesh filename="package://robotiq_arg2f_model_visualization/meshes/robotiq_arg2f_140_inner_knuckle.stl"/>
      </geometry>
    </collision>
  </link>
  <joint name="right_gripper_finger_joint" type="revolute">
    <origin rpy="2.29579632679 0 0" xyz="0 -0.030601 0.054905"/>
    <parent link="right_gripper_robotiq_arg2f_base_link"/>
    <child link="right_gripper_left_outer_knuckle"/>
    <axis xyz="-1 0 0"/>
    <limit effort="1000" lower="0" upper="0.775" velocity="2.0"/>
  </joint>
  <joint name="right_gripper_left_outer_finger_joint" type="fixed">
    <origin rpy="0 0 0" xyz="0 0.01821998610742 0.0260018192872234"/>
    <parent link="right_gripper_left_outer_knuckle"/>
    <child link="right_gripper_left_outer_finger"/>
    <axis xyz="1 0 0"/>
  </joint>
  <joint name="right_gripper_left_inner_knuckle_joint" type="revolute">
    <origin rpy="2.29579632679 0 0.0" xyz="0 -0.0127 0.06142"/>
    <parent link="right_gripper_robotiq_arg2f_base_link"/>
    <child link="right_gripper_left_inner_knuckle"/>
    <axis xyz="1 0 0"/>
    <limit effort="1000" lower="0" upper="0.8757" velocity="2.0"/>
    <mimic joint="right_gripper_finger_joint" multiplier="-1" offset="0"/>
  </joint>
  <joint name="right_gripper_left_inner_finger_joint" type="revolute">
    <origin rpy="-.725 0 0" xyz="0 0.0817554015893473 -0.0282203446692936"/>
    <parent link="right_gripper_left_outer_finger"/>
    <child link="right_gripper_left_inner_finger"/>
    <axis xyz="1 0 0"/>
    <limit effort="1000" lower="0" upper="0.8757" velocity="2.0"/>
    <mimic joint="right_gripper_finger_joint" multiplier="1" offset="0"/>
  </joint>
  <joint name="right_gripper_right_outer_knuckle_joint" type="revolute">
    <origin rpy="2.29579632679 0 3.14159265359" xyz="0 0.030601 0.054905"/>
    <parent link="right_gripper_robotiq_arg2f_base_link"/>
    <child link="right_gripper_right_outer_knuckle"/>
    <axis xyz="1 0 0"/>
    <limit effort="1000" lower="0" upper="0.725" velocity="2.0"/>
    <mimic joint="right_gripper_finger_joint" multiplier="-1" offset="0"/>
  </joint>
  <joint name="right_gripper_right_outer_finger_joint" type="fixed">
    <origin rpy="0 0 0" xyz="0 0.01821998610742 0.0260018192872234"/>
    <parent link="right_gripper_right_outer_knuckle"/>
    <child link="right_gripper_right_outer_finger"/>
    <axis xyz="1 0 0"/>
  </joint>
  <joint name="right_gripper_right_inner_knuckle_joint" type="revolute">
    <origin rpy="2.29579632679 0 -3.14159265359" xyz="0 0.0127 0.06142"/>
    <parent link="right_gripper_robotiq_arg2f_base_link"/>
    <child link="right_gripper_right_inner_knuckle"/>
    <axis xyz="1 0 0"/>
    <limit effort="1000" lower="0" upper="0.8757" velocity="2.0"/>
    <mimic joint="right_gripper_finger_joint" multiplier="-1" offset="0"/>
  </joint>
  <joint name="right_gripper_right_inner_finger_joint" type="revolute">
    <origin rpy="-.725 0 0" xyz="0 0.0817554015893473 -0.0282203446692936"/>
    <parent link="right_gripper_right_outer_finger"/>
    <child link="right_gripper_right_inner_finger"/>
    <axis xyz="1 0 0"/>
    <limit effort="1000" lower="0" upper="0.8757" velocity="2.0"/>
    <mimic joint="right_gripper_finger_joint" multiplier="1" offset="0"/>
  </joint>
  <transmission name="right_gripper_finger_joint_trans">
    <type>transmission_interface/SimpleTransmission</type>
    <joint name="right_gripper_finger_joint">
      <hardwareInterface>PositionJointInterface</hardwareInterface>
    </joint>
    <actuator name="right_gripper_finger_joint_motor">
      <mechanicalReduction>1</mechanicalReduction>
    </actuator>
  </transmission>
  <!--Joint from the adapter plate to the robotiq gripper coupling-->
  <joint name="right_gripper_gripper_coupling_joint" type="fixed">
    <origin rpy="-1.57079632679 0 0" xyz="0 0.0160 0"/>
    <parent link="arm_right_link_gripper_adapter_plate"/>
    <child link="arm_right_link_robotiq_coupling"/>
  </joint>
  <!--Joint from the robotiq coupling to the gripper itself-->
  <joint name="right_gripper_joint" type="fixed">
    <origin rpy="0 0 3.14159265359" xyz="0 0.0 0.0039"/>
    <parent link="arm_right_link_robotiq_coupling"/>
    <child link="right_gripper_robotiq_arg2f_base_link"/>
  </joint>
  <!--LINKS********************************************************************************************************************************-->
  <!--Aluminium Adapter plate for Robotiq coupling and CSDA10F arm flange-->
  <link name="arm_left_link_gripper_adapter_plate">
    <visual>
      <origin rpy="0 0 0" xyz="0 0 0"/>
      <geometry>
        <mesh filename="package://invite_motoman_support/meshes/robotiq-yaskawa_adapter_plate.stl" scale="0.001 0.001 0.001"/>
      </geometry>
      <material name="Aluminium">
        <color rgba="0.816 0.816 0.816 1.0"/>
      </material>
    </visual>
    <collision>
      <origin rpy="1.57079632679 0 0" xyz="0 0.0045 0"/>
      <geometry>
        <cylinder length="0.009" radius="0.038"/>
      </geometry>
      <material name="yellow"/>
    </collision>
  </link>
  <!--Robotiq coupling, that connects the gripper with the Adapter plate; this part host the cable connections of the gripper-->
  <link name="arm_left_link_robotiq_coupling">
    <visual>
      <origin rpy="0 0 0" xyz="0 0 0"/>
      <geometry>
        <mesh filename="package://invite_motoman_support/meshes/robotiq_gripper_coupling.stl" scale="0.001 0.001 0.001"/>
      </geometry>
      <material name="light_balck">
        <color rgba="0.17 0.17 0.17 1.0"/>
      </material>
    </visual>
    <collision>
      <origin rpy="0 0 0" xyz="0 0 0"/>
      <geometry>
        <cylinder length="0.0135" radius="0.038"/>
      </geometry>
      <material name="yellow"/>
    </collision>
  </link>
  --&gt;
		
  <!--Dynpick adaptor plate, which connects the force sensor with the robot flange-->
  <link name="arm_left_link_force_sensor_adapter_plate">
    <visual>
      <origin rpy="0 0 0" xyz="0.00 0 0.0095"/>
      <geometry>
        <cylinder length="0.019" radius="0.043"/>
      </geometry>
      <material name="aluminium">
        <color rgba="0.917 0.917 0.917 1.0"/>
      </material>
    </visual>
    <collision>
      <origin rpy="0 0 0" xyz="0 0 0.0095"/>
      <geometry>
        <cylinder length="0.019" radius="0.043"/>
      </geometry>
      <material name="yellow"/>
    </collision>
  </link>
  --&gt;
		
  <!--Dynpick adaptor plate, which connects the force sensor with the robot flange-->
  <link name="arm_left_link_force_sensor">
    <visual>
      <origin rpy="0 0 0" xyz="0 0 0"/>
      <geometry>
        <cylinder length="0.040" radius="0.045"/>
      </geometry>
      <material name="red-aluminium">
        <color rgba="0.721 0 0 1.0"/>
      </material>
    </visual>
    <collision>
      <origin rpy="0 0 0" xyz="0 0 0"/>
      <geometry>
        <cylinder length="0.040" radius="0.0455"/>
      </geometry>
      <material name="yellow"/>
    </collision>
  </link>
  --&gt;


  <!--Joints ******************************************************************************************************************-->
  <!--Joint force sensor adaptor plate to force sensor-->
  <joint name="arm_left_gripper_flange_joint" type="fixed">
    <origin rpy="0 0 0" xyz="0 0 0.039"/>
    <parent link="arm_left_link_force_sensor_adapter_plate"/>
    <child link="arm_left_link_force_sensor"/>
  </joint>
  <!--Joint from the force sensor to the gripper adaptor plate-->
  <joint name="arm_left_gripper_force_sensor_joint" type="fixed">
    <origin rpy="1.57079632679 0 0" xyz="0 0 0.02"/>
    <parent link="arm_left_link_force_sensor"/>
    <child link="arm_left_link_gripper_adapter_plate"/>
  </joint>
  <!--Joint from the adapter plate to the robotiq gripper coupling-->
  <joint name="arm_left_gripper_coupling_joint" type="fixed">
    <origin rpy="-1.57079632679 0 0" xyz="0 0.0160 0"/>
    <parent link="arm_left_link_gripper_adapter_plate"/>
    <child link="arm_left_link_robotiq_coupling"/>
  </joint>
  <!-- base -->
  <joint name="arm_left_link_robotiq_coupling_arm_left_base_joint" type="fixed">
    <origin rpy="0 0 3.14159265359" xyz="0 0 0.0039"/>
    <parent link="arm_left_link_robotiq_coupling"/>
    <child link="arm_left_base"/>
  </joint>
  <link name="arm_left_base">
    <!-- inertial>
				<mass value="0.1"/>
				<origin xyz="0 0 0.055"  />
				<cylinder_inertia radius="0.06" length="0.11" mass="0.1"/>
			</inertial -->
    <visual>
      <geometry>
        <mesh filename="package://robotiq_2f_model/model/meshes/2f85/visual/base.dae" scale="0.001 0.001 0.001"/>
      </geometry>
    </visual>
    <collision>
      <geometry>
        <mesh filename="package://robotiq_2f_model/model/meshes/2f85/collision/base.stl" scale="0.001 0.001 0.001"/>
      </geometry>
    </collision>
  </link>
  <!-- right finger -->
  <joint name="arm_left_right_driver_joint" type="revolute">
    <origin rpy="0 0 0" xyz="0 0.0306011 0.054904"/>
    <parent link="arm_left_base"/>
    <child link="arm_left_right_driver"/>
    <axis xyz="1 0 0"/>
    <limit effort="60" lower="0.0" upper="0.872664444444" velocity="1.91986177778"/>
  </joint>
  <link name="arm_left_right_driver">
    <!-- inertial>
				<mass value="0.1"/>
				<origin xyz="0 0 0.055"  />
				<cylinder_inertia radius="0.06" length="0.11" mass="0.1"/>
			</inertial -->
    <visual>
      <geometry>
        <mesh filename="package://robotiq_2f_model/model/meshes/2f85/visual/driver.dae" scale="0.001 0.001 0.001"/>
      </geometry>
    </visual>
    <collision>
      <geometry>
        <mesh filename="package://robotiq_2f_model/model/meshes/2f85/collision/driver.stl" scale="0.001 0.001 0.001"/>
      </geometry>
    </collision>
  </link>
  <joint name="arm_left_right_coupler_joint" type="fixed">
    <origin rpy="0 0 0" xyz="0 0.0315 -0.0041"/>
    <parent link="arm_left_right_driver"/>
    <child link="arm_left_right_coupler"/>
  </joint>
  <link name="arm_left_right_coupler">
    <!-- inertial>
				<mass value="0.1"/>
				<origin xyz="0 0 0.055"  />
				<cylinder_inertia radius="0.06" length="0.11" mass="0.1"/>
			</inertial -->
    <visual>
      <geometry>
        <mesh filename="package://robotiq_2f_model/model/meshes/2f85/visual/coupler.dae" scale="0.001 0.001 0.001"/>
      </geometry>
    </visual>
    <collision>
      <geometry>
        <mesh filename="package://robotiq_2f_model/model/meshes/2f85/collision/coupler.stl" scale="0.001 0.001 0.001"/>
      </geometry>
    </collision>
  </link>
  <joint name="arm_left_right_follower_joint" type="revolute">
    <origin rpy="0 0 0" xyz="0 0.0061 0.0471"/>
    <parent link="arm_left_right_coupler"/>
    <child link="arm_left_right_follower"/>
    <axis xyz="1 0 0"/>
    <limit effort="176" lower="-2.96705911111" upper="2.96705911111" velocity="1.91986177778"/>
    <mimic joint="arm_left_right_driver_joint" multiplier="-1"/>
  </joint>
  <link name="arm_left_right_follower">
    <visual>
      <geometry>
        <mesh filename="package://robotiq_2f_model/model/meshes/2f85/visual/follower.dae" scale="0.001 0.001 0.001"/>
      </geometry>
    </visual>
    <collision>
      <geometry>
        <mesh filename="package://robotiq_2f_model/model/meshes/2f85/collision/follower.stl" scale="0.001 0.001 0.001"/>
      </geometry>
    </collision>
  </link>
  <joint name="arm_left_right_pad_joint" type="fixed">
    <parent link="arm_left_right_follower"/>
    <child link="arm_left_right_pad"/>
  </joint>
  <link name="arm_left_right_pad">
    <!-- inertial>
				<mass value="0.1"/>
				<origin xyz="0 0 0.055"  />
				<cylinder_inertia radius="0.06" length="0.11" mass="0.1"/>
			</inertial -->
    <visual>
      <geometry>
        <mesh filename="package://robotiq_2f_model/model/meshes/2f85/visual/pad.dae" scale="0.001 0.001 0.001"/>
      </geometry>
    </visual>
    <collision>
      <geometry>
        <mesh filename="package://robotiq_2f_model/model/meshes/2f85/collision/pad.stl" scale="0.001 0.001 0.001"/>
      </geometry>
    </collision>
  </link>
  <joint name="arm_left_right_spring_link_joint" type="revolute">
    <origin rpy="0 0 0" xyz="0 0.012 0.0614"/>
    <parent link="arm_left_base"/>
    <child link="arm_left_right_spring_link"/>
    <axis xyz="1 0 0"/>
    <limit effort="176" lower="-2.96705911111" upper="2.96705911111" velocity="1.91986177778"/>
    <mimic joint="arm_left_right_driver_joint" multiplier="1"/>
  </joint>
  <link name="arm_left_right_spring_link">
    <!-- inertial>
				<mass value="0.1"/>
				<origin xyz="0 0 0.055"  />
				<cylinder_inertia radius="0.06" length="0.11" mass="0.1"/>
			</inertial -->
    <visual>
      <geometry>
        <mesh filename="package://robotiq_2f_model/model/meshes/2f85/visual/spring_link.dae" scale="0.001 0.001 0.001"/>
      </geometry>
    </visual>
    <collision>
      <geometry>
        <mesh filename="package://robotiq_2f_model/model/meshes/2f85/collision/spring_link.stl" scale="0.001 0.001 0.001"/>
      </geometry>
    </collision>
  </link>
  <!-- left finger -->
  <joint name="arm_left_left_driver_joint" type="revolute">
    <origin rpy="0 0 3.141592653589793" xyz="0 -0.0306011 0.054904"/>
    <parent link="arm_left_base"/>
    <child link="arm_left_left_driver"/>
    <axis xyz="1 0 0"/>
    <limit effort="176" lower="0.0" upper="0.715584844444" velocity="1.91986177778"/>
    <mimic joint="arm_left_right_driver_joint" multiplier="1"/>
  </joint>
  <link name="arm_left_left_driver">
    <!-- inertial>
				<mass value="0.1"/>
				<origin xyz="0 0 0.055"  />
				<cylinder_inertia radius="0.06" length="0.11" mass="0.1"/>
			</inertial -->
    <visual>
      <geometry>
        <mesh filename="package://robotiq_2f_model/model/meshes/2f85/visual/driver.dae" scale="0.001 0.001 0.001"/>
      </geometry>
    </visual>
    <collision>
      <geometry>
        <mesh filename="package://robotiq_2f_model/model/meshes/2f85/collision/driver.stl" scale="0.001 0.001 0.001"/>
      </geometry>
    </collision>
  </link>
  <joint name="arm_left_left_coupler_joint" type="fixed">
    <origin rpy="0 0 0" xyz="0 0.0315 -0.0041"/>
    <parent link="arm_left_left_driver"/>
    <child link="arm_left_left_coupler"/>
  </joint>
  <link name="arm_left_left_coupler">
    <!-- inertial>
				<mass value="0.1"/>
				<origin xyz="0 0 0.055"  />
				<cylinder_inertia radius="0.06" length="0.11" mass="0.1"/>
			</inertial -->
    <visual>
      <geometry>
        <mesh filename="package://robotiq_2f_model/model/meshes/2f85/visual/coupler.dae" scale="0.001 0.001 0.001"/>
      </geometry>
    </visual>
    <collision>
      <geometry>
        <mesh filename="package://robotiq_2f_model/model/meshes/2f85/collision/coupler.stl" scale="0.001 0.001 0.001"/>
      </geometry>
    </collision>
  </link>
  <joint name="arm_left_left_follower_joint" type="revolute">
    <origin rpy="0 0 0" xyz="0 0.0061 0.0471"/>
    <parent link="arm_left_left_coupler"/>
    <child link="arm_left_left_follower"/>
    <axis xyz="1 0 0"/>
    <limit effort="176" lower="-2.96705911111" upper="2.96705911111" velocity="1.91986177778"/>
    <mimic joint="arm_left_right_driver_joint" multiplier="-1"/>
  </joint>
  <link name="arm_left_left_follower">
    <visual>
      <geometry>
        <mesh filename="package://robotiq_2f_model/model/meshes/2f85/visual/follower.dae" scale="0.001 0.001 0.001"/>
      </geometry>
    </visual>
    <collision>
      <geometry>
        <mesh filename="package://robotiq_2f_model/model/meshes/2f85/collision/follower.stl" scale="0.001 0.001 0.001"/>
      </geometry>
    </collision>
  </link>
  <joint name="arm_left_left_pad_joint" type="fixed">
    <parent link="arm_left_left_follower"/>
    <child link="arm_left_left_pad"/>
  </joint>
  <link name="arm_left_left_pad">
    <!-- inertial>
				<mass value="0.1"/>
				<origin xyz="0 0 0.055"  />
				<cylinder_inertia radius="0.06" length="0.11" mass="0.1"/>
			</inertial -->
    <visual>
      <geometry>
        <mesh filename="package://robotiq_2f_model/model/meshes/2f85/visual/pad.dae" scale="0.001 0.001 0.001"/>
      </geometry>
    </visual>
    <collision>
      <geometry>
        <mesh filename="package://robotiq_2f_model/model/meshes/2f85/collision/pad.stl" scale="0.001 0.001 0.001"/>
      </geometry>
    </collision>
  </link>
  <joint name="arm_left_left_spring_link_joint" type="revolute">
    <origin rpy="0 0 3.141592653589793" xyz="0 -0.012 0.0614"/>
    <parent link="arm_left_base"/>
    <child link="arm_left_left_spring_link"/>
    <axis xyz="1 0 0"/>
    <limit effort="176" lower="-2.96705911111" upper="2.96705911111" velocity="1.91986177778"/>
    <mimic joint="arm_left_right_driver_joint" multiplier="1"/>
  </joint>
  <link name="arm_left_left_spring_link">
    <!-- inertial>
				<mass value="0.1"/>
				<origin xyz="0 0 0.055"  />
				<cylinder_inertia radius="0.06" length="0.11" mass="0.1"/>
			</inertial -->
    <visual>
      <geometry>
        <mesh filename="package://robotiq_2f_model/model/meshes/2f85/visual/spring_link.dae" scale="0.001 0.001 0.001"/>
      </geometry>
    </visual>
    <collision>
      <geometry>
        <mesh filename="package://robotiq_2f_model/model/meshes/2f85/collision/spring_link.stl" scale="0.001 0.001 0.001"/>
      </geometry>
    </collision>
  </link>
  <transmission name="arm_left_right_driver_trans">
    <type>transmission_interface/SimpleTransmission</type>
    <joint name="arm_left_right_driver_joint">
      <hardwareInterface>PositionJointInterface</hardwareInterface>
    </joint>
    <actuator name="arm_left_right_driver_motor">
      <mechanicalReduction>1</mechanicalReduction>
    </actuator>
  </transmission>
  <!--Joints joining the grippers to the robot-->
  <joint name="left_gripper_to_robot_joint" type="fixed">
    <parent link="arm_left_link_tool0"/>
    <child link="arm_left_link_force_sensor_adapter_plate"/>
    <origin rpy="0 0 1.94464585257" xyz="0 0 0"/>
    <axis xyz="0 0 1"/>
  </joint>
  <joint name="right_gripper_to_robot_joint" type="fixed">
    <parent link="arm_right_link_tool0"/>
    <child link="arm_right_link_gripper_adapter_plate"/>
    <origin rpy="1.57079632679 0 0" xyz="0 0 0"/>
    <axis xyz="0 0 1"/>
  </joint>
  <!--Define the TCP of the grippers -->
  <link name="arm_right_link_tcp"/>
  <link name="arm_left_link_tcp"/>
  <!--Define the position of the TCP with respect to the arm flange-->
  <joint name="arm_right_joint_tcp" type="fixed">
    <origin rpy="0 0 0" xyz="0 0 0.1994"/>
    <parent link="arm_right_link_tool0"/>
    <child link="arm_right_link_tcp"/>
  </joint>
  <joint name="arm_left_joint_tcp" type="fixed">
    <origin rpy="0 0 1.94464585257" xyz="0 0 0.2094"/>
    <parent link="arm_left_link_tool0"/>
    <child link="arm_left_link_tcp"/>
  </joint>
</robot>

